<?xml version="1.0"?>
<robot name="example_model" xmlns:xacro="http://www.ros.org/wiki/xacro">
  
  <link name="world"/>
  
  <joint name="fixed to ground" type="fixed">
    <parent link="world"/>
    <child link="bed"/>
    <origin xyz="0 0 0"/>
    <axis xyz="0 0 0"/>
  </joint>
  
  <link name="bed">
    <visual>
      <origin xyz="0 0 2.5" rpy="0 0 0"/>
      <geometry>
	<box size="0.4 0.4 0.2"/>
      </geometry>
    </visual>

    <collision>
      <origin xyz="0 0 2.5" rpy="0 0 0"/>
      <geometry>
	<box size="0.4 0.4 0.2"/>
      </geometry>
    </collision>

    <inertial>
      <origin xyz="0 0 0" rpy="0 0 0"/>
      <mass value="1"/>
      <inertia
	ixx="0.01" ixy="0.0" ixz="0.0"
	iyy="0.01" iyz="0.0" 
	izz="0.01"/>
    </inertial>
  </link>

  <joint name="joint1" type="revolute">
    <parent link="bed"/>
    <child link="link1"/>
    <origin xyz="0 0 2.5"/>
    <axis xyz="0 1 0"/>
    <limit effort="1000" lower="-1.57" upper="1.57" velocity="10"/>
  </joint>

  <link name="link1">
    <visual>
      <origin xyz="0 0 -0.5" rpy="0 0 0"/>
      <geometry>
	<cylinder length="1" radius="0.05"/>
      </geometry>
    </visual>
   
    <collision>
      <origin xyz="0 0 -0.5" rpy="0 0 0"/>
      <geometry>
	<cylinder length="1" radius="0.05"/>
      </geometry>
    </collision>

    <inertial>
      <origin xyz="0 0 -0.5" rpy="0 0 0"/>
      <mass value="1"/>
      <inertia
	ixx="0.01" ixy="0.0" ixz="0.0"
	iyy="0.01" iyz="0.0" 
	izz="0.01"/>      
    </inertial>     
  </link>

  <joint name="joint2" type="revolute">
    <parent link="link1"/>
    <child link="link2"/>
    <origin xyz="0 0 -1"/>
    <axis xyz="0 1 0"/>
    <limit effort="1000" lower="-1.57" upper="1.57" velocity="10"/>
  </joint>

  <link name="link2">
    <visual>
      <origin xyz="0 0 -0.5" rpy="0 0 0"/>
      <geometry>
	<cylinder length="1" radius="0.05"/>
      </geometry>
    </visual>
   
    <collision>
      <origin xyz="0 0 -0.5" rpy="0 0 0"/>
      <geometry>
	<cylinder length="1" radius="0.05"/>
      </geometry>
    </collision>

    <inertial>
      <origin xyz="0 0 -0.5" rpy="0 0 0"/>
      <mass value="1"/>
      <inertia
	ixx="0.01" ixy="0.0" ixz="0.0"
	iyy="0.01" iyz="0.0" 
	izz="0.01"/>      
    </inertial>     
  </link>
</robot>
